{"uuid": "5f6e040f-b915-4434-9d4b-c160dd93ecd4", "children": ["168ef16a-ff9d-4406-96b0-a0d0ac14ec9e"], "befores": [{"name": "xunit_setup_class_fixture_TestMpArticle", "status": "broken", "statusDetails": {"message": "selenium.common.exceptions.WebDriverException: Message: unknown error: Chrome failed to start: crashed.\n  (unknown error: DevToolsActivePort file doesn't exist)\n  (The process started from chrome location C:\\Users\\LXZ\\AppData\\Local\\Google\\Chrome\\Application\\chrome.exe is no longer running, so ChromeDriver is assuming that Chrome has crashed.)\n\n", "trace": "  File \"E:\\Users\\LXZ\\AppData\\Local\\Programs\\Python\\Python38-32\\lib\\site-packages\\pluggy\\callers.py\", line 187, in _multicall\n    res = hook_impl.function(*args)\n  File \"E:\\Users\\LXZ\\AppData\\Local\\Programs\\Python\\Python38-32\\lib\\site-packages\\_pytest\\fixtures.py\", line 1126, in pytest_fixture_setup\n    result = call_fixture_func(fixturefunc, request, kwargs)\n  File \"E:\\Users\\LXZ\\AppData\\Local\\Programs\\Python\\Python38-32\\lib\\site-packages\\_pytest\\fixtures.py\", line 925, in call_fixture_func\n    fixture_result = next(generator)\n  File \"E:\\Users\\LXZ\\AppData\\Local\\Programs\\Python\\Python38-32\\lib\\site-packages\\_pytest\\python.py\", line 811, in xunit_setup_class_fixture\n    _call_with_optional_argument(func, self.obj)\n  File \"E:\\Users\\LXZ\\AppData\\Local\\Programs\\Python\\Python38-32\\lib\\site-packages\\_pytest\\python.py\", line 739, in _call_with_optional_argument\n    func(arg)\n  File \"D:\\F盘的数据\\PycharmProjects\\import_project\\uiAutoTestBoke\\scripts\\test02_mp_article.py\", line 10, in setup_class\n    driver = GetDriver().get_web_driver(page.url_mp)\n  File \"D:\\F盘的数据\\PycharmProjects\\import_project\\uiAutoTestBoke\\tools\\get_driver.py\", line 14, in get_web_driver\n    cls.__web_driver = webdriver.Chrome()\n  File \"E:\\Users\\LXZ\\AppData\\Local\\Programs\\Python\\Python38-32\\lib\\site-packages\\selenium-3.141.0-py3.8.egg\\selenium\\webdriver\\chrome\\webdriver.py\", line 76, in __init__\n    RemoteWebDriver.__init__(\n  File \"E:\\Users\\LXZ\\AppData\\Local\\Programs\\Python\\Python38-32\\lib\\site-packages\\selenium-3.141.0-py3.8.egg\\selenium\\webdriver\\remote\\webdriver.py\", line 157, in __init__\n    self.start_session(capabilities, browser_profile)\n  File \"E:\\Users\\LXZ\\AppData\\Local\\Programs\\Python\\Python38-32\\lib\\site-packages\\selenium-3.141.0-py3.8.egg\\selenium\\webdriver\\remote\\webdriver.py\", line 252, in start_session\n    response = self.execute(Command.NEW_SESSION, parameters)\n  File \"E:\\Users\\LXZ\\AppData\\Local\\Programs\\Python\\Python38-32\\lib\\site-packages\\selenium-3.141.0-py3.8.egg\\selenium\\webdriver\\remote\\webdriver.py\", line 321, in execute\n    self.error_handler.check_response(response)\n  File \"E:\\Users\\LXZ\\AppData\\Local\\Programs\\Python\\Python38-32\\lib\\site-packages\\selenium-3.141.0-py3.8.egg\\selenium\\webdriver\\remote\\errorhandler.py\", line 242, in check_response\n    raise exception_class(message, screen, stacktrace)\n"}, "start": 1616251723789, "stop": 1616251729833}], "start": 1616251723789, "stop": 1616251730028}