{"uuid": "db044046-b818-46ba-8df2-39ff0265adea", "children": ["58fb67f7-a89b-4849-b2a2-cf61f161e39d"], "befores": [{"name": "xunit_setup_class_fixture_TestAppArticle", "status": "broken", "statusDetails": {"message": "selenium.common.exceptions.WebDriverException: Message: An unknown server-side error occurred while processing the command. Original error: Cannot start the 'com.cnblogs.xamarinandroid' application. Visit https://github.com/appium/appium/blob/master/docs/en/writing-running-appium/android/activity-startup.md for troubleshooting. Original error: Error executing adbExec. Original error: 'Command ''E:\\\\Program Files (x86)\\\\androidsdk\\\\platform-tools\\\\adb.exe' -P 5037 -s 192.168.241.102\\:5555 shell am start -W -n com.cnblogs.xamarinandroid/crc64c2c99c61e0e508d5.MainActivity -S' timed out after 20000ms'. Try to increase the 20000ms adb execution timeout represented by 'adbExecTimeout' capability\n\n", "trace": "  File \"E:\\Users\\LXZ\\AppData\\Local\\Programs\\Python\\Python38-32\\lib\\site-packages\\pluggy\\callers.py\", line 187, in _multicall\n    res = hook_impl.function(*args)\n  File \"E:\\Users\\LXZ\\AppData\\Local\\Programs\\Python\\Python38-32\\lib\\site-packages\\_pytest\\fixtures.py\", line 1126, in pytest_fixture_setup\n    result = call_fixture_func(fixturefunc, request, kwargs)\n  File \"E:\\Users\\LXZ\\AppData\\Local\\Programs\\Python\\Python38-32\\lib\\site-packages\\_pytest\\fixtures.py\", line 925, in call_fixture_func\n    fixture_result = next(generator)\n  File \"E:\\Users\\LXZ\\AppData\\Local\\Programs\\Python\\Python38-32\\lib\\site-packages\\_pytest\\python.py\", line 811, in xunit_setup_class_fixture\n    _call_with_optional_argument(func, self.obj)\n  File \"E:\\Users\\LXZ\\AppData\\Local\\Programs\\Python\\Python38-32\\lib\\site-packages\\_pytest\\python.py\", line 739, in _call_with_optional_argument\n    func(arg)\n  File \"D:\\F盘的数据\\PycharmProjects\\import_project\\uiAutoTestBoke\\scripts\\test06_app_article.py\", line 10, in setup_class\n    app_driver = GetDriver().get_app_driver()\n  File \"D:\\F盘的数据\\PycharmProjects\\import_project\\uiAutoTestBoke\\tools\\get_driver.py\", line 40, in get_app_driver\n    cls.__app_driver = appium.webdriver.Remote('http://localhost:4723/wd/hub', desired_caps)\n  File \"E:\\Users\\LXZ\\AppData\\Local\\Programs\\Python\\Python38-32\\lib\\site-packages\\appium\\webdriver\\webdriver.py\", line 151, in __init__\n    super().__init__(\n  File \"E:\\Users\\LXZ\\AppData\\Local\\Programs\\Python\\Python38-32\\lib\\site-packages\\selenium-3.141.0-py3.8.egg\\selenium\\webdriver\\remote\\webdriver.py\", line 157, in __init__\n    self.start_session(capabilities, browser_profile)\n  File \"E:\\Users\\LXZ\\AppData\\Local\\Programs\\Python\\Python38-32\\lib\\site-packages\\appium\\webdriver\\webdriver.py\", line 225, in start_session\n    response = self.execute(RemoteCommand.NEW_SESSION, parameters)\n  File \"E:\\Users\\LXZ\\AppData\\Local\\Programs\\Python\\Python38-32\\lib\\site-packages\\selenium-3.141.0-py3.8.egg\\selenium\\webdriver\\remote\\webdriver.py\", line 321, in execute\n    self.error_handler.check_response(response)\n  File \"E:\\Users\\LXZ\\AppData\\Local\\Programs\\Python\\Python38-32\\lib\\site-packages\\selenium-3.141.0-py3.8.egg\\selenium\\webdriver\\remote\\errorhandler.py\", line 242, in check_response\n    raise exception_class(message, screen, stacktrace)\n"}, "start": 1616339287249, "stop": 1616339319933}], "start": 1616339287249, "stop": 1616339320230}