{"uuid": "a0e18779-3542-48e2-aac5-531f34dcecb8", "children": ["eea4422d-d401-4de3-9351-aa79106191c1"], "befores": [{"name": "xunit_setup_class_fixture_TestAppArticle", "status": "broken", "statusDetails": {"message": "urllib3.exceptions.MaxRetryError: HTTPConnectionPool(host='localhost', port=4723): Max retries exceeded with url: /wd/hub/session (Caused by NewConnectionError('<urllib3.connection.HTTPConnection object at 0x04643490>: Failed to establish a new connection: [WinError 10061] 由于目标计算机积极拒绝，无法连接。'))\n", "trace": "  File \"E:\\Users\\LXZ\\AppData\\Local\\Programs\\Python\\Python38-32\\lib\\site-packages\\pluggy\\callers.py\", line 187, in _multicall\n    res = hook_impl.function(*args)\n  File \"E:\\Users\\LXZ\\AppData\\Local\\Programs\\Python\\Python38-32\\lib\\site-packages\\_pytest\\fixtures.py\", line 1126, in pytest_fixture_setup\n    result = call_fixture_func(fixturefunc, request, kwargs)\n  File \"E:\\Users\\LXZ\\AppData\\Local\\Programs\\Python\\Python38-32\\lib\\site-packages\\_pytest\\fixtures.py\", line 925, in call_fixture_func\n    fixture_result = next(generator)\n  File \"E:\\Users\\LXZ\\AppData\\Local\\Programs\\Python\\Python38-32\\lib\\site-packages\\_pytest\\python.py\", line 811, in xunit_setup_class_fixture\n    _call_with_optional_argument(func, self.obj)\n  File \"E:\\Users\\LXZ\\AppData\\Local\\Programs\\Python\\Python38-32\\lib\\site-packages\\_pytest\\python.py\", line 739, in _call_with_optional_argument\n    func(arg)\n  File \"D:\\F盘的数据\\PycharmProjects\\import_project\\uiAutoTestBoke\\scripts\\test06_app_article.py\", line 10, in setup_class\n    app_driver = GetDriver().get_app_driver()\n  File \"D:\\F盘的数据\\PycharmProjects\\import_project\\uiAutoTestBoke\\tools\\get_driver.py\", line 40, in get_app_driver\n    cls.__app_driver = appium.webdriver.Remote('http://localhost:4723/wd/hub', desired_caps)\n  File \"E:\\Users\\LXZ\\AppData\\Local\\Programs\\Python\\Python38-32\\lib\\site-packages\\appium\\webdriver\\webdriver.py\", line 151, in __init__\n    super().__init__(\n  File \"E:\\Users\\LXZ\\AppData\\Local\\Programs\\Python\\Python38-32\\lib\\site-packages\\selenium-3.141.0-py3.8.egg\\selenium\\webdriver\\remote\\webdriver.py\", line 157, in __init__\n    self.start_session(capabilities, browser_profile)\n  File \"E:\\Users\\LXZ\\AppData\\Local\\Programs\\Python\\Python38-32\\lib\\site-packages\\appium\\webdriver\\webdriver.py\", line 225, in start_session\n    response = self.execute(RemoteCommand.NEW_SESSION, parameters)\n  File \"E:\\Users\\LXZ\\AppData\\Local\\Programs\\Python\\Python38-32\\lib\\site-packages\\selenium-3.141.0-py3.8.egg\\selenium\\webdriver\\remote\\webdriver.py\", line 319, in execute\n    response = self.command_executor.execute(driver_command, params)\n  File \"E:\\Users\\LXZ\\AppData\\Local\\Programs\\Python\\Python38-32\\lib\\site-packages\\selenium-3.141.0-py3.8.egg\\selenium\\webdriver\\remote\\remote_connection.py\", line 374, in execute\n    return self._request(command_info[0], url, body=data)\n  File \"E:\\Users\\LXZ\\AppData\\Local\\Programs\\Python\\Python38-32\\lib\\site-packages\\selenium-3.141.0-py3.8.egg\\selenium\\webdriver\\remote\\remote_connection.py\", line 397, in _request\n    resp = self._conn.request(method, url, body=body, headers=headers)\n  File \"E:\\Users\\LXZ\\AppData\\Local\\Programs\\Python\\Python38-32\\lib\\site-packages\\urllib3\\request.py\", line 79, in request\n    return self.request_encode_body(\n  File \"E:\\Users\\LXZ\\AppData\\Local\\Programs\\Python\\Python38-32\\lib\\site-packages\\urllib3\\request.py\", line 171, in request_encode_body\n    return self.urlopen(method, url, **extra_kw)\n  File \"E:\\Users\\LXZ\\AppData\\Local\\Programs\\Python\\Python38-32\\lib\\site-packages\\urllib3\\poolmanager.py\", line 336, in urlopen\n    response = conn.urlopen(method, u.request_uri, **kw)\n  File \"E:\\Users\\LXZ\\AppData\\Local\\Programs\\Python\\Python38-32\\lib\\site-packages\\urllib3\\connectionpool.py\", line 754, in urlopen\n    return self.urlopen(\n  File \"E:\\Users\\LXZ\\AppData\\Local\\Programs\\Python\\Python38-32\\lib\\site-packages\\urllib3\\connectionpool.py\", line 754, in urlopen\n    return self.urlopen(\n  File \"E:\\Users\\LXZ\\AppData\\Local\\Programs\\Python\\Python38-32\\lib\\site-packages\\urllib3\\connectionpool.py\", line 754, in urlopen\n    return self.urlopen(\n  File \"E:\\Users\\LXZ\\AppData\\Local\\Programs\\Python\\Python38-32\\lib\\site-packages\\urllib3\\connectionpool.py\", line 726, in urlopen\n    retries = retries.increment(\n  File \"E:\\Users\\LXZ\\AppData\\Local\\Programs\\Python\\Python38-32\\lib\\site-packages\\urllib3\\util\\retry.py\", line 439, in increment\n    raise MaxRetryError(_pool, url, error or ResponseError(cause))\n"}, "start": 1616338376373, "stop": 1616338412520}], "start": 1616338376373, "stop": 1616338413133}